Workbook

Sheet Cover
B3: Maruti Suzuki India Limited
B4: FY2026 Budgeted Profit & Loss, Balance Sheet and Cash Flow
B5: Financial Planning & Analysis (FP&A) Live Project — Deliverable Workbook
B8: Prepared for | C8: Caplexus Capital — Live Project, FP&A Analyst Track
B9: Company analysed | C9: Maruti Suzuki India Limited (NSE: MARUTI, BSE: 532500)
B10: Financial basis | C10: Consolidated financials, Rs. Million unless stated
B11: Historical period | C11: FY2022 – FY2025 (years ended 31 March)
B12: Budget year | C12: FY2026 (1 April 2025 – 31 March 2026)
B13: Budget prepared as of | C13: Q1 FY2026 (April–June 2025), using information publicly available up to that point
B14: Prepared on | C14: 06 August 2026
B16: Contents
B17: 1. Historical Financials (FY2022–FY2025)
B18: 2. Key Business Metrics & Drivers
B19: 3. Macro Assumptions (FY2026)
B20: 4. Assumptions (Micro / Line-item)
B21: 5. Revenue Budget (Volume x Realization)
B22: 6. Cost Budget
B23: 7. Budgeted Profit & Loss
B24: 8. Budgeted Balance Sheet
B25: 9. Budgeted Cash Flow Statement
B26: 10. Sensitivity Analysis
B28: A note on methodology
B29: Revenue and cost figures for FY2022–FY2025 are drawn from Maruti Suzuki's published consolidated results and cross-checked against reported PBT and PAT (see Historical Financials tab for line-by-line sourcing). The single 'Operating Expenses' line was split into Cost of Materials Consumed, Employee Benefit Expense and Other Operating Expenses using proportions derived from Maruti Suzuki's own historical standalone cost structure (an estimation methodology, documented on the Historical Financials tab) since the source dataset did not carry this split. Macro and industry assumptions reflect information available as of Q1 FY2026 (April-June 2025) — i.e. this budget is built prospectively, as an FP&A analyst would have built it at the start of the year, not with hindsight of how FY2026 actually played out.

Sheet Historical Financials
A1: Maruti Suzuki India Ltd — Historical Financials
A2: Consolidated basis, Rs. Million, years ended 31 March. Source: company results / annual reports (see notes column H).
B4: Particulars | C4: FY2022 | D4: FY2023 | E4: FY2024 | F4: FY2025 | H4: Source / Note
A5: Profit & Loss Account
B6: Revenue from Operations | C6: 883298 | D6: 1184099 | E6: 1418582 | F6: 1529130 | H6: Consolidated revenue from operations, as reported in quarterly/annual results filed with BSE/NSE.
B7: Less: Cost of Materials Consumed (COGS) | C7: 661183 | D7: 857380 | E7: 999664 | F7: 1079530 | H7: Estimated: Opex split using MSIL's historical standalone common-size cost ratios (materials + change in inventory), applied to the Opex total below and cross-checked to reported PBT/PAT. See methodology note below.
B8: Less: Employee Benefit Expense | C8: 40470 | D8: 52488 | E8: 62647 | F8: 68916 | H8: Estimated using the same common-size cost-structure methodology (see below).
B9: Less: Other Operating Expenses | C9: 124583 | D9: 143287 | E9: 171008 | F9: 179121 | H9: Estimated balancing item = Total Operating Expenses − COGS − Employee Cost (ensures the three lines tie exactly to the known, reported Opex total).
B10: Total Operating Expenses | C10: =SUM(C7:C9) -> 826236 | D10: =SUM(D7:D9) -> 1053155 | E10: =SUM(E7:E9) -> 1233319 | F10: =SUM(F7:F9) -> 1327567 | H10: Check: ties to Revenue − EBITDA per company results (row below).
B11: EBITDA | C11: =C6-C10 -> 57062 | D11: =D6-D10 -> 130944 | E11: =E6-E10 -> 185263 | F11: =F6-F10 -> 201563 | H11: Revenue minus Total Operating Expenses. Reconciles to company-reported Operating Profit within rounding.
B12: EBITDA Margin % | C12: =C11/C6 -> 0.064601075 | D12: =D11/D6 -> 0.11058535 | E12: =E11/E6 -> 0.13059731 | F12: =F11/F6 -> 0.13181548 | H12: EBITDA / Revenue from Operations
B13: Less: Depreciation & Amortisation | C13: 27890 | D13: 48460 | E13: 52558 | F13: 56082 | H13: As reported in consolidated financial statements.
B14: EBIT (Operating Profit) | C14: =C11-C13 -> 29172 | D14: =D11-D13 -> 82484 | E14: =E11-E13 -> 132705 | F14: =F11-F13 -> 145481
B15: Add: Other Income | C15: 17447 | D15: 22647 | E15: 40935 | F15: 50222 | H15: Investment/treasury income, as reported.
B16: Less: Finance Cost | C16: 1266 | D16: 2523 | E16: 1936 | F16: 1942
B17: Add: Share of Profit of Associates | C17: 1464 | D17: 1558 | E17: 2263 | F17: 2152
B18: Add: Share of Profit of Joint Ventures | C18: 155 | D18: 216 | E18: 278 | F18: 287
B19: Profit Before Tax (PBT) | C19: =C14+C15-C16+C17+C18 -> 46972 | D19: =D14+D15-D16+D17+D18 -> 104382 | E19: =E14+E15-E16+E17+E18 -> 174245 | F19: =F14+F15-F16+F17+F18 -> 196200 | H19: Cross-checked: matches company-reported consolidated PBT for all 4 years (Rs 46,972 / 104,382 / 174,245 / 196,200 mn).
B20: Less: Tax Expense | C20: 8177 | D20: 21745 | E20: 39363 | F20: 51198
B21: Profit After Tax (PAT) | C21: =C19-C20 -> 38795 | D21: =D19-D20 -> 82637 | E21: =E19-E20 -> 134882 | F21: =F19-F20 -> 145002 | H21: Cross-checked: matches company-reported consolidated PAT (Rs 38,795 / 82,637 / 134,882 / 145,002 mn).
B22: PAT Margin % | C22: =C21/C6 -> 0.043920625 | D22: =D21/D6 -> 0.069788928 | E22: =E21/E6 -> 0.095082272 | F22: =F21/F6 -> 0.09482647
B24: Effective Tax Rate | C24: =C20/C19 -> 0.17408243 | D24: =D20/D19 -> 0.20832136 | E24: =E20/E19 -> 0.22590605 | F24: =F20/F19 -> 0.26094801
B25: Add: Other Comprehensive Income (OCI) | C25: 3129 | D25: 586 | E25: 2669 | F25: 337
B26: Less: Dividend Paid | C26: 13594 | D26: 18125 | E26: 27187 | F26: 39300
B27: Retained Earnings for the Year | C27: =C21+C25-C26 -> 28330 | D27: =D21+D25-D26 -> 65098 | E27: =E21+E25-E26 -> 110364 | F27: =F21+F25-F26 -> 106039
B28: Dividend Payout Ratio | C28: =C26/C21 -> 0.35040598 | D28: =D26/D21 -> 0.21933274 | E28: =E26/E21 -> 0.20156136 | F28: =F26/F21 -> 0.27103074
A30: Balance Sheet (Summary)
B31: Shareholders' Equity | C31: 553335 | D31: 746002 | E31: 856360 | F31: 962399 | H31: Equity share capital + Other equity (reserves), consolidated.
B32: Borrowings & Lease Liabilities | C32: 4255 | D32: 12476 | E32: 1186 | F32: 870
B33: Other Non-Current Liabilities | C33: 22656 | D33: 29935 | E33: 36953 | F33: 51028 | H33: Provisions, deferred tax liabilities and other non-current liabilities (net of borrowings already shown above).
B34: TOTAL LIABILITIES & EQUITY | C34: =SUM(C31:C33) -> 580246 | D34: =SUM(D31:D33) -> 788413 | E34: =SUM(E31:E33) -> 894499 | F34: =SUM(F31:F33) -> 1014297
B36: Fixed Assets (Net Block + CWIP) | C36: 160435 | D36: 314476 | E36: 349154 | F36: 400198
B37: Intangible Assets | C37: 6402 | D37: 6368 | E37: 6842 | F37: 8919
B38: Investments | C38: 420347 | D38: 491843 | E38: 572960 | F38: 662654 | H38: Current + non-current investments (incl. mutual funds, bonds, associates/JV carrying value).
B39: Other Non-Current Assets | C39: 32438 | D39: 34475 | E39: 37336 | F39: 36081
B40: Cash and Bank Balances | C40: 30422 | D40: 27485 | E40: 28274 | F40: 5529
B41: Remaining Net Current Assets | C41: -69798 | D41: -86234 | E41: -100067 | F41: -99084 | H41: Net working capital excl. cash & investments (receivables + inventory − payables & other current liabilities). Structurally negative — MSIL runs on supplier/dealer float, typical for a dominant OEM.
B42: TOTAL ASSETS | C42: =SUM(C36:C41) -> 580246 | D42: =SUM(D36:D41) -> 788413 | E42: =SUM(E36:E41) -> 894499 | F42: =SUM(F36:F41) -> 1014297
B43: Balance Check (Assets − Liab.&Equity) | C43: =C42-C34 -> 0 | D43: =D42-D34 -> 0 | E43: =E42-E34 -> 0 | F43: =F42-F34 -> 0
A45: Volume & Realisation Bridge (Standalone units sold; company press releases)
...

Sheet Metrics & Drivers
A1: Key Business Metrics & Drivers Map
A2: Maruti Suzuki India Ltd — how each metric is expected to behave, and the operational driver(s) behind it.
B4: Metric | C4: FY2024 | D4: FY2025 | E4: FY2026E | F4: Operational Driver(s) | G4: Why It Matters to the Budget
B5: Revenue growth % | C5: ='Historical Financials'!E6/'Historical Financials'!D6-1 -> 0.19802652 | D5: ='Historical Financials'!F6/'Historical Financials'!E6-1 -> 0.077928523 | E5: =Assumptions!D8 -> 0.10775 | F5: Volume growth x realisation/mix growth (see below) | G5: Top-line driver for the whole P&L; every cost line below is scaled off Revenue.
B6: Volume growth % (units) | C6: ='Historical Financials'!E52 -> 0.086035041 | D6: ='Historical Financials'!F52 -> 0.046336315 | E6: =Assumptions!D6 -> 0.055 | F6: Domestic PV demand (SIAM/ICRA industry growth) + Kharkhoda capacity ramp-up + export push | G6: Separates 'how many cars' from 'how much per car' — critical for capacity & working-capital planning.
B7: Realisation / ASP growth % | C7: ='Historical Financials'!E53 -> 0.10311958 | D7: ='Historical Financials'!F53 -> 0.030193167 | E7: =Assumptions!D7 -> 0.05 | F7: April-2025 price hike (~4%) + mix shift toward UVs/SUVs and e-Vitara EV exports | G7: Shows margin quality of growth — price/mix-led growth protects margins better than pure volume growth.
B8: COGS % of Revenue | C8: ='Historical Financials'!E7/'Historical Financials'!E6 -> 0.70469243 | D8: ='Historical Financials'!F7/'Historical Financials'!F6 -> 0.7059766 | E8: =Assumptions!D10 -> 0.713 | F8: Steel/aluminium/precious-metal input costs, import content (Suzuki royalty, JPY-linked parts), localisation % | G8: Single largest cost line (~70% of revenue) — the biggest swing factor for EBITDA.
B9: Employee Cost % of Revenue | C9: ='Historical Financials'!E8/'Historical Financials'!E6 -> 0.044161705 | D9: ='Historical Financials'!F8/'Historical Financials'!F6 -> 0.045068765 | E9: =Assumptions!D11 -> 0.047 | F9: Annual wage increments, new hiring for Kharkhoda plant ramp-up | G9: Structural/sticky cost; doesn't flex down quickly if volumes disappoint.
B10: Other Opex % of Revenue | C10: ='Historical Financials'!E9/'Historical Financials'!E6 -> 0.12054855 | D10: ='Historical Financials'!F9/'Historical Financials'!F6 -> 0.11713916 | E10: =Assumptions!D12 -> 0.11 | F10: Advertising & sales promotion (e-Vitara EV launch), freight, warranty, R&D | G10: Discretionary spend — the easiest lever to pull in a downside scenario.
B11: EBITDA Margin % | C11: ='Historical Financials'!E12 -> 0.13059731 | D11: ='Historical Financials'!F12 -> 0.13181548 | E11: ='Budgeted P&L'!D11 -> 0.13 | F11: 1 minus (COGS%+Employee%+OtherOpex%) — net effect of pricing power vs. cost inflation | G11: Headline operating profitability metric tracked by the Board and analysts.
B12: D&A % of prior-year Fixed+Intangible Assets | C12: ='Historical Financials'!E13/('Historical Financials'!D36+'Historical Financials'!D37) -> 0.1638117 | D12: ='Historical Financials'!F13/('Historical Financials'!E36+'Historical Financials'!E37) -> 0.15753548 | E12: =Assumptions!D15 -> 0.16 | F12: Capex intensity (Kharkhoda plant, new tooling for EV/SUV models) | G12: Rising capex base (new plants) mechanically increases D&A each year.
B13: Effective Tax Rate | C13: ='Historical Financials'!E24 -> 0.22590605 | D13: ='Historical Financials'!F24 -> 0.26094801 | E13: =Assumptions!D22 -> 0.2591 | F13: Glide-path toward the 25.168% statutory rate as one-off deferred-tax items (e.g. FY25 indexation withdrawal impact) roll off | G13: Directly drives PAT for a given PBT.
B14: Working Capital (Net Current Assets, % of Revenue) | C14: ='Historical Financials'!E41/'Historical Financials'!E6 -> -0.070540159 | D14: ='Historical Financials'!F41/'Historical Financials'!F6 -> -0.06479763 | E14: =Assumptions!D28 -> -0.075 | F14: Dealer/supplier payment terms — MSIL runs negative working capital (payables > receivables+inventory) | G14: Negative working capital is a structural source of cash for MSIL; a key balance-sheet driver.
B15: Capex Intensity (Fixed Assets % of Revenue) | C15: ='Historical Financials'!E36/'Historical Financials'!E6 -> 0.24612888 | D15: ='Historical Financials'!F36/'Historical Financials'!F6 -> 0.26171614 | E15: =Assumptions!D25 -> 0.23 | F15: Kharkhoda Plant-2, Gujarat D-line, EV tooling and capacity expansion under 'Maruti Suzuki 3.0' | G15: Determines Balance Sheet growth and depreciation trajectory.
B16: Dividend Payout Ratio | C16: ='Historical Financials'!E28 -> 0.20156136 | D16: ='Historical Financials'!F28 -> 0.27103074 | E16: =Assumptions!D33 -> 0.2 | F16: Board policy — historically ~20-27% of PAT; raised progressively as profitability scaled | G16: Determines how much of PAT is retained to fund growth vs. returned to shareholders.

Sheet Macro Assumptions
A1: Macro Assumptions — FY2026
A2: Set as of Q1 FY2026 (April-June 2025), using information available at that point in time. Not updated with hindsight.
B4: Macro Variable | C4: FY2026 Assumption | D4: Rationale | E4: Source
B5: Real GDP Growth (India, FY2026) | C5: 6.5% | D5: RBI's April-2025 Monetary Policy Report projected FY2026 real GDP growth at 6.5%, alongside a 25bp repo rate cut to 6.0%, as growth was recovering from a soft H1 FY25 while inflation eased. | E5: RBI Monetary Policy Report, April 2025; PIB press release, 9-Apr-2025
B6: CPI Inflation (FY2026) | C6: ~4.0% (within target band) | D6: RBI's April-2025 policy projected FY2026 inflation to remain within the 4% target band, supported by moderating food prices; underpinned the shift to an accommodative policy stance. | E6: RBI Monetary Policy Report, April 2025
B7: RBI Repo Rate / Interest-Rate Stance | C7: Easing cycle; repo rate ~6.0%, accommodative stance | D7: Two consecutive 25bp cuts (Feb-25: 6.5%→6.25%; Apr-25: 6.25%→6.00%) with a shift to 'accommodative' stance — lower cost of working-capital and vehicle-finance borrowing supports both MSIL and its dealers/customers. | E7: RBI MPC resolutions, Feb & Apr 2025 (Business Standard, PIB)
B8: INR/USD Exchange Rate | C8: Gradual depreciation (mid-single-digit %, directional) | D8: The rupee had already weakened >6% following the April-2025 US tariff announcement (up to ~26% reciprocal tariff on Indian goods); a continued mild depreciation bias was the base case for FY26, raising the cost of dollar/yen-denominated imports and Suzuki royalty payments. | E8: Business Standard, Apr-2025 tariff coverage; NAGA/BookMyForex FX outlook commentary
B9: Steel & Key Input Commodity Costs | C9: Firm-to-rising | D9: World Steel Association projected India steel demand growth of ~9% for calendar 2026; raw-material cost volatility (iron ore, coking coal) flagged as a continuing risk — a headwind for MSIL's largest cost line (materials consumed). | E9: World Steel Association / industry steel-price outlook coverage, late-2025
B10: Auto Industry (SIAM/ICRA) — PV Wholesale Growth, FY2026 | C10: Modest: 1%-4% | D10: ICRA (Aug-2025) projected FY26 domestic PV wholesale growth of just 1-4%, citing elevated channel inventory and a high FY25 base; MSIL management itself guided to industry growth of ~1-2% domestically, with company-specific growth to come from exports (+20% targeted) and new-model/capacity additions rather than a broad market recovery. | E10: ICRA industry note (Business Standard, 29-Aug-2025); Reuters, MSIL Q4 FY25 earnings call
B12: How the macro view feeds the micro (line-item) assumptions:
B13: Modest industry volume growth + MSIL's own capacity/export initiatives -> Volume growth assumption on the Assumptions tab. Price hike (partly a response to input-cost inflation) + mix shift -> Realisation growth assumption. Firm steel/commodity outlook -> COGS % of Revenue assumption trending up, not down. Easing rate cycle -> Finance Cost held flat rather than assumed to rise. See the Assumptions tab for exact linkage.

Sheet Assumptions
A1: FY2026 Budget Assumptions
A2: One row per assumption, with FY2025 actual base and a documented rationale, per SOW requirements.
B4: Assumption | C4: FY2025 Actual (base) | D4: FY2026 Assumption | E4: Rationale
A5: Revenue Assumptions
B6: Volume growth % | C6: ='Historical Financials'!F52 -> 0.046336315 | D6: 0.055 | E6: Blend of ~3% domestic volume growth (ICRA/management guide industry to +1-4% given high FY25 base & channel inventory) weighted 85%, and ~20% export volume growth (MSIL's own FY26 target, Kharkhoda capacity + e-Vitara EV exports) weighted 15% -> 0.85x3%+0.15x20% ≈ 5.5%.
B7: Realisation / ASP growth % | C7: ='Historical Financials'!F53 -> 0.030193167 | D7: 0.05 | E7: ~4% list-price hike effective April 2025 (announced across models) plus ~1% from mix shift toward higher-ASP UVs/SUVs and the e-Vitara EV.
B8: Revenue growth % (derived) | D8: =(1+D6)*(1+D7)-1 -> 0.10775 | E8: Revenue growth = (1+Volume growth) x (1+Realisation growth) minus 1. Cross-checks closely to the 11% revenue growth used independently in the FCFF/DCF equity-research model for the same company.
A9: Cost Assumptions
B10: Cost of Materials Consumed (COGS), % of Revenue | C10: ='Historical Financials'!F7/'Historical Financials'!F6 -> 0.7059766 | D10: 0.713 | E10: +0.7pp vs FY25 (70.6%): steel/commodity cost outlook is firm-to-rising (WSA projects ~9% India steel demand growth for CY26) and the company carries meaningful import/royalty content; partly offset by the April-25 price hike.
B11: Employee Benefit Expense, % of Revenue | C11: ='Historical Financials'!F8/'Historical Financials'!F6 -> 0.045068765 | D11: 0.047 | E11: +0.19pp vs FY25 (4.51%): annual wage increments plus incremental hiring to ramp up the new Kharkhoda plant.
B12: Other Operating Expenses, % of Revenue | C12: ='Historical Financials'!F9/'Historical Financials'!F6 -> 0.11713916 | D12: 0.11 | E12: -0.71pp vs FY25 (11.71%): operating leverage as fixed SG&A spreads over a larger revenue base, netted against higher one-off advertising/promotion spend for the e-Vitara EV launch.
B13: Total Operating Expenses, % of Revenue (check) | C13: ='Historical Financials'!F10/'Historical Financials'!F6 -> 0.86818452 | D13: =D10+D11+D12 -> 0.87 | E13: Sum of the three lines above; +0.18pp vs FY25's 86.8%.
A14: Other P&L Assumptions
B15: Depreciation & Amortisation, % of prior-year (Fixed+Intangible Assets) | C15: ='Historical Financials'!F13/('Historical Financials'!F36+'Historical Financials'!F37) -> 0.13708059 | D15: 0.16 | E15: Held at the FY25 ratio (~16%) — a rising capex base (Kharkhoda, Gujarat D-line) mechanically lifts the Rs mn depreciation charge even at a flat %.
B16: Finance Cost (Rs mn) | C16: ='Historical Financials'!F16 -> 1942 | D16: ='Historical Financials'!F16 -> 1942 | E16: Held flat YoY: MSIL is almost debt-free (Borrowings ~Rs 870mn) and the RBI easing cycle (repo rate down to ~6.0%) keeps incremental borrowing costs low.
B17: Other Income, % of prior-year Investments | C17: ='Historical Financials'!F15/'Historical Financials'!E38 -> 0.087653588 | D17: 0.075 | E17: Held at the FY25 ratio; treasury/investment income scales with the growing investment book.
B18: Share of Profit of Associates, growth % YoY | C18: ='Historical Financials'!F17/'Historical Financials'!E17-1 -> -0.049049934 | D18: 0.05 | E18: Modest 5% growth in line with historical trend (JV/associate earnings, incl. Suzuki Motor Gujarat-linked entities).
B19: Share of Profit of Joint Ventures, growth % YoY | C19: ='Historical Financials'!F18/'Historical Financials'!E18-1 -> 0.032374101 | D19: 0.1 | E19: 10% growth, consistent with the historical 3-year trend.
B22: Effective Tax Rate | C22: ='Historical Financials'!F24 -> 0.26094801 | D22: 0.2591 | E22: Gradual glide-path toward the 25.168% statutory rate (one-fifth of the gap closed per year) as the FY25 one-off deferred-tax impact (indexation-benefit withdrawal on debt-fund gains) rolls off.
A24: Balance Sheet Assumptions
B25: Fixed Assets, % of Revenue | C25: ='Historical Financials'!F36/'Historical Financials'!F6 -> 0.26171614 | D25: 0.23 | E25: Held at ~23% of revenue: continued capex under 'Maruti Suzuki 3.0' (Kharkhoda Plant-2, Gujarat D-line, EV tooling) keeps pace with revenue growth.
B26: Intangible Assets, growth % YoY | C26: ='Historical Financials'!F37/'Historical Financials'!E37-1 -> 0.30356621 | D26: 0.095 | E26: 9.5% growth — continued investment in product development/software (EV platform, connected-car tech).
B27: Other Non-Current Assets, growth % YoY | C27: ='Historical Financials'!F39/'Historical Financials'!E39-1 -> -0.03361367 | D27: 0.18 | E27: 18% growth, in line with the historical 3-year trend.
B28: Remaining Net Current Assets, % of Revenue | C28: ='Historical Financials'!F41/'Historical Financials'!F6 -> -0.06479763 | D28: -0.075 | E28: Held at ~-7.5% of revenue: MSIL's negative working-capital model (payables from dealers/suppliers exceed receivables+inventory) is structural and has been stable for years.
B29: Cash & Bank Balances (Rs mn) | C29: ='Historical Financials'!F40 -> 5529 | D29: ='Historical Financials'!F40 -> 5529 | E29: Held flat YoY, consistent with MSIL's practice of sweeping surplus cash into the Investments book rather than building idle cash balances.
B30: Borrowings & Lease Liabilities (Rs mn) | C30: ='Historical Financials'!F32 -> 870 | D30: ='Historical Financials'!F32 -> 870 | E30: Held flat YoY — MSIL is almost debt-free and self-funds capex from operating cash flow.
B31: Other Non-Current Liabilities, growth % YoY | C31: ='Historical Financials'!F33/'Historical Financials'!E33-1 -> 0.38088924 | D31: 0.1 | E31: 10% growth, in line with the historical trend (provisions, deferred tax liabilities).
B33: Dividend Payout Ratio | C33: ='Historical Financials'!F28 -> 0.27103074 | D33: 0.2 | E33: Held at 20% of PAT (source DCF/equity-research model's own assumption; consistent with MSIL's recent payout history of ~20-27%), balancing shareholder returns against funding the multi-year capex programme.

Sheet Revenue Budget
A1: FY2026 Revenue Budget
A2: Bottom-up build: Volume x Realisation per vehicle.
B4: Particulars | C4: FY2025 Actual | D4: FY2026 Budget | E4: Basis
A5: Volume
B6: Total Vehicles Sold (units) | C6: ='Historical Financials'!F47 -> 2234266 | D6: =C6*(1+Assumptions!D6) -> 2357150.6 | E6: FY2025 actual x (1 + Volume growth % from Assumptions tab)
B7: Volume Growth % | C7: ='Historical Financials'!F52 -> 0.046336315 | D7: =Assumptions!D6 -> 0.055 | E7: Linked from Assumptions tab
A8: Realisation
B9: Realisation per Vehicle (Rs) | C9: ='Historical Financials'!F51 -> 684399.26 | D9: =C9*(1+Assumptions!D7) -> 718619.22 | E9: FY2025 actual x (1 + Realisation growth % from Assumptions tab)
B10: Realisation Growth % | C10: ='Historical Financials'!F53 -> 0.030193167 | D10: =Assumptions!D7 -> 0.05 | E10: Linked from Assumptions tab
A11: Revenue Build-up
B12: Revenue from Operations (Volume x Realisation) | C12: ='Historical Financials'!F6 -> 1529130 | D12: =D6*D9/1000000 -> 1693893.8 | E12: Volume (units) x Realisation (Rs/unit) / 1,000,000 = Rs mn
B13: Revenue from Operations (cross-check: straight growth %) | C13: ='Historical Financials'!F6 -> 1529130 | D13: =C12*(1+Assumptions!D8) -> 1693893.8 | E13: FY2025 Revenue x (1 + Revenue growth % derived on Assumptions tab)
B14: Difference (Volume x Realisation vs. straight growth %) | D14: =D12-D13 -> 0 | E14: Should be ~0 — confirms the two build methods agree.
A16: FY2026 Budgeted Revenue from Operations
B17: Revenue from Operations, FY2026 Budget (Rs mn) | D17: =D12 -> 1693893.8
B19: Volume growth (5.5%) and Realisation growth (5.0%) combine to a Revenue growth of ~10.8%, close to (and cross-validating) the 11% revenue growth assumption used independently in the source FCFF/DCF equity-research model for the same company.

Sheet Cost Budget
A1: FY2026 Cost Budget
A2: Each cost line driven by its own assumption — no flat across-the-board growth rate.
B4: Particulars | C4: FY2025 Actual | D4: FY2026 Budget | E4: Basis
A5: Revenue (linked from Revenue Budget tab)
B6: Revenue from Operations | C6: ='Historical Financials'!F6 -> 1529130 | D6: ='Revenue Budget'!D17 -> 1693893.8 | E6: Linked from the Revenue Budget tab.
A7: Operating Cost Lines
B8: Cost of Materials Consumed (COGS) | C8: ='Historical Financials'!F7 -> 1079530 | D8: =D6*Assumptions!D10 -> 1207746.2 | E8: FY2026 Revenue x COGS % of Revenue (Assumptions tab)
B9: Employee Benefit Expense | C9: ='Historical Financials'!F8 -> 68916 | D9: =D6*Assumptions!D11 -> 79613.007 | E9: FY2026 Revenue x Employee Cost % of Revenue (Assumptions tab)
B10: Other Operating Expenses | C10: ='Historical Financials'!F9 -> 179121 | D10: =D6*Assumptions!D12 -> 186328.31 | E10: FY2026 Revenue x Other Opex % of Revenue (Assumptions tab)
B11: Total Operating Expenses | C11: ='Historical Financials'!F10 -> 1327567 | D11: =D8+D9+D10 -> 1473687.6 | E11: Sum of the three lines above.
B12: EBITDA | C12: ='Historical Financials'!F11 -> 201563 | D12: =D6-D11 -> 220206.19 | E12: Revenue minus Total Operating Expenses.
B13: EBITDA Margin % | C13: ='Historical Financials'!F12 -> 0.13181548 | D13: =D12/D6 -> 0.13 | E13: EBITDA / Revenue
A14: Depreciation & Finance Cost
B15: Depreciation & Amortisation | C15: ='Historical Financials'!F13 -> 56082 | D15: =Assumptions!D15*('Historical Financials'!F36+'Historical Financials'!F37) -> 65458.72 | E15: FY2026 D&A % (Assumptions tab) x prior-year (FY2025) Fixed + Intangible Assets.
B16: EBIT (Operating Profit) | C16: ='Historical Financials'!F14 -> 145481 | D16: =D12-D15 -> 154747.47 | E16: EBITDA minus D&A.

Sheet Budgeted P&L
A1: Maruti Suzuki India Ltd — Budgeted Profit & Loss, FY2026
A2: Consolidated basis, Rs. Million. Fully linked to the Revenue Budget, Cost Budget and Assumptions tabs.
B4: Particulars | C4: FY2025 Actual | D4: FY2026 Budget | E4: Growth % | F4: Basis / Link
B5: Revenue from Operations | C5: ='Historical Financials'!F6 -> 1529130 | D5: ='Revenue Budget'!D17 -> 1693893.8 | E5: =D5/C5-1 -> 0.10775 | F5: Revenue Budget tab
B6: Less: Cost of Materials Consumed | C6: ='Historical Financials'!F7 -> 1079530 | D6: ='Cost Budget'!D8 -> 1207746.2 | E6: =D6/C6-1 -> 0.11877044 | F6: Cost Budget tab
B7: Less: Employee Benefit Expense | C7: ='Historical Financials'!F8 -> 68916 | D7: ='Cost Budget'!D9 -> 79613.007 | E7: =D7/C7-1 -> 0.15521804 | F7: Cost Budget tab
B8: Less: Other Operating Expenses | C8: ='Historical Financials'!F9 -> 179121 | D8: ='Cost Budget'!D10 -> 186328.31 | E8: =D8/C8-1 -> 0.040237121 | F8: Cost Budget tab
B9: Total Operating Expenses | C9: ='Historical Financials'!F10 -> 1327567 | D9: ='Cost Budget'!D11 -> 1473687.6 | E9: =D9/C9-1 -> 0.11006644
B10: EBITDA | C10: ='Historical Financials'!F11 -> 201563 | D10: ='Cost Budget'!D12 -> 220206.19 | E10: =D10/C10-1 -> 0.092493109
B11: EBITDA Margin % | C11: ='Historical Financials'!F12 -> 0.13181548 | D11: =D10/D5 -> 0.13
B12: Less: Depreciation & Amortisation | C12: ='Historical Financials'!F13 -> 56082 | D12: ='Cost Budget'!D15 -> 65458.72 | E12: =D12/C12-1 -> 0.1671966 | F12: Cost Budget tab
B13: EBIT (Operating Profit) | C13: ='Historical Financials'!F14 -> 145481 | D13: =D10-D12 -> 154747.47 | E13: =D13/C13-1 -> 0.063695386
B14: Add: Other Income | C14: ='Historical Financials'!F15 -> 50222 | D14: =Assumptions!D17*'Historical Financials'!F38 -> 49699.05 | E14: =D14/C14-1 -> -0.010412767 | F14: FY2026 % (Assumptions D17) x FY2025 Investments
B15: Less: Finance Cost | C15: ='Historical Financials'!F16 -> 1942 | D15: =Assumptions!D16 -> 1942 | E15: =D15/C15-1 -> 0 | F15: Assumptions tab (held flat YoY)
B16: Add: Share of Profit of Associates | C16: ='Historical Financials'!F17 -> 2152 | D16: ='Historical Financials'!F17*(1+Assumptions!D18) -> 2259.6 | E16: =D16/C16-1 -> 0.05 | F16: FY2025 x (1+growth %, Assumptions D18)
B17: Add: Share of Profit of Joint Ventures | C17: ='Historical Financials'!F18 -> 287 | D17: ='Historical Financials'!F18*(1+Assumptions!D19) -> 315.7 | E17: =D17/C17-1 -> 0.1 | F17: FY2025 x (1+growth %, Assumptions D19)
B18: Profit Before Tax (PBT) | C18: ='Historical Financials'!F19 -> 196200 | D18: =D13+D14-D15+D16+D17 -> 205079.82 | E18: =D18/C18-1 -> 0.045259014
B19: Less: Tax Expense | C19: ='Historical Financials'!F20 -> 51198 | D19: =D18*Assumptions!D22 -> 53136.181 | E19: =D19/C19-1 -> 0.037856576 | F19: PBT x Effective Tax Rate (Assumptions tab)
B20: Profit After Tax (PAT) | C20: ='Historical Financials'!F21 -> 145002 | D20: =D18-D19 -> 151943.64 | E20: =D20/C20-1 -> 0.047872702
B21: PAT Margin % | C21: ='Historical Financials'!F22 -> 0.09482647 | D21: =D20/D5 -> 0.089700807
B23: Add: Other Comprehensive Income | C23: ='Historical Financials'!F25 -> 337 | D23: ='Historical Financials'!F25 -> 337 | E23: =D23/C23-1 -> 0 | F23: Held flat YoY (immaterial, non-operating mark-to-market item — same convention as the source DCF model)
B24: Less: Dividend Paid | C24: ='Historical Financials'!F26 -> 39300 | D24: =D20*Assumptions!D33 -> 30388.728 | E24: =D24/C24-1 -> -0.22674994 | F24: PAT x Dividend Payout Ratio (Assumptions tab)
B25: Retained Earnings for the Year | C25: ='Historical Financials'!F27 -> 106039 | D25: =D20+D23-D24 -> 121891.91 | E25: =D25/C25-1 -> 0.14950075

Sheet Budgeted Balance Sheet
A1: Maruti Suzuki India Ltd — Budgeted Balance Sheet, FY2026
A2: Consolidated basis, Rs. Million. Investments is the balancing (plug) line — see note below.
B4: Particulars | C4: FY2025 Actual | D4: FY2026 Budget | E4: Basis / Link
A5: Liabilities & Equity
B6: Shareholders' Equity | C6: ='Historical Financials'!F31 -> 962399 | D6: =C6+'Budgeted P&L'!D25 -> 1084290.9 | E6: FY2025 Equity + FY2026 Retained Earnings (Budgeted P&L tab)
B7: Borrowings & Lease Liabilities | C7: ='Historical Financials'!F32 -> 870 | D7: =Assumptions!D30 -> 870 | E7: Held flat YoY (Assumptions tab)
B8: Other Non-Current Liabilities | C8: ='Historical Financials'!F33 -> 51028 | D8: =C8*(1+Assumptions!D31) -> 56130.8 | E8: FY2025 x (1+growth %, Assumptions tab)
B9: TOTAL LIABILITIES & EQUITY | C9: ='Historical Financials'!F34 -> 1014297 | D9: =D6+D7+D8 -> 1141291.7
A11: Assets
B12: Fixed Assets (Net Block + CWIP) | C12: ='Historical Financials'!F36 -> 400198 | D12: =Assumptions!D25*'Budgeted P&L'!D5 -> 389595.56 | E12: Fixed Assets % of Revenue (Assumptions tab) x FY2026 Budgeted Revenue
B13: Intangible Assets | C13: ='Historical Financials'!F37 -> 8919 | D13: =C13*(1+Assumptions!D26) -> 9766.305 | E13: FY2025 x (1+growth %, Assumptions tab)
B14: Other Non-Current Assets | C14: ='Historical Financials'!F39 -> 36081 | D14: =C14*(1+Assumptions!D27) -> 42575.58 | E14: FY2025 x (1+growth %, Assumptions tab)
B15: Cash and Bank Balances | C15: ='Historical Financials'!F40 -> 5529 | D15: =Assumptions!D29 -> 5529 | E15: Held flat YoY (Assumptions tab)
B16: Remaining Net Current Assets | C16: ='Historical Financials'!F41 -> -99084 | D16: =Assumptions!D28*'Budgeted P&L'!D5 -> -127042.03 | E16: Remaining Net Current Assets % of Revenue (Assumptions tab) x FY2026 Revenue
B17: Investments (balancing figure — see note) | C17: ='Historical Financials'!F38 -> 662654 | D17: =D9-D12-D13-D14-D15-D16 -> 820867.29 | E17: PLUG: set so that Total Assets = Total Liabilities + Equity. Represents surplus cash swept into mutual funds/bonds/other financial assets — the same mechanism used in the source DCF model.
B18: TOTAL ASSETS | C18: ='Historical Financials'!F42 -> 1014297 | D18: =D12+D13+D17+D14+D15+D16 -> 1141291.7
B19: Balance Check (Assets − Liab.&Equity) | C19: ='Historical Financials'!F43 -> 0 | D19: =D18-D9 -> 0
B21: Investments is deliberately used as the balancing (plug) line, exactly as in most driver-based 3-statement models: every other asset and liability line is independently driven (see Assumptions tab); Investments then absorbs whatever surplus cash generation (or funding gap) falls out of those choices, so the Balance Sheet ties by construction. The Balance Check row above should read 0 in both years.

Sheet Budgeted Cash Flow
A1: Maruti Suzuki India Ltd — Budgeted Cash Flow Statement, FY2026
A2: Indirect method, Rs. Million, consolidated basis.
B4: Particulars | C4: FY2026 Budget | D4: Basis / Link
A5: Cash Flow from Operating Activities
B6: Profit After Tax | C6: ='Budgeted P&L'!D20 -> 151943.64 | D6: Budgeted P&L tab
B7: Add: Depreciation & Amortisation | C7: ='Budgeted P&L'!D12 -> 65458.72 | D7: Budgeted P&L tab
B8: Less: Non-cash share of Associates'/JV's profit (net) | C8: =-('Budgeted P&L'!D16+'Budgeted P&L'!D17) -> -2575.3 | D8: Non-cash income included in PAT but not received as operating cash (equity-pickup method)
B9: Add/(Less): Decrease/(Increase) in Net Current Assets | C9: ='Historical Financials'!F41-'Budgeted Balance Sheet'!D16 -> 27958.032 | D9: FY2025 Net Current Assets − FY2026 Budget (a more negative NCA is a source of cash)
B10: Add: Increase in Other Non-Current Liabilities | C10: ='Budgeted Balance Sheet'!D8-'Historical Financials'!F33 -> 5102.8 | D10: FY2026 Budget − FY2025 Actual
B11: Net Cash from Operating Activities (A) | C11: =SUM(C6:C10) -> 247887.89
A13: Cash Flow from Investing Activities
B14: Less: Capital Expenditure | C14: =-(('Budgeted Balance Sheet'!D12+'Budgeted Balance Sheet'!D13)-('Historical Financials'!F36+'Historical Financials'!F37)+'Budgeted P&L'!D12) -> -55703.589 | D14: Increase in (Fixed+Intangible Assets) + D&A added back = gross capex for the year
B15: Less: Investments Made (net of non-cash equity pickup & OCI) | C15: =-('Budgeted Balance Sheet'!D17-'Historical Financials'!F38-'Budgeted P&L'!D16-'Budgeted P&L'!D17-'Budgeted P&L'!D23) -> -155300.99 | D15: Increase in the Investments book, net of the non-cash equity-pickup (Assoc./JV profit) and OCI portion of that increase already excluded from CFO above — isolates the cash actually deployed.
B16: Less: Increase in Other Non-Current Assets | C16: =-('Budgeted Balance Sheet'!D14-'Historical Financials'!F39) -> -6494.58 | D16: FY2026 Budget − FY2025 Actual
B17: Net Cash used in Investing Activities (B) | C17: =SUM(C14:C16) -> -217499.16
A19: Cash Flow from Financing Activities
B20: Less: Dividend Paid | C20: =-'Budgeted P&L'!D24 -> -30388.728 | D20: Budgeted P&L tab
B21: Add/(Less): Net Change in Borrowings | C21: ='Budgeted Balance Sheet'!D7-'Historical Financials'!F32 -> 0 | D21: FY2026 Budget − FY2025 Actual (held flat -> nil)
B22: Net Cash from/(used in) Financing Activities (C) | C22: =SUM(C20:C21) -> -30388.728
B24: Net Increase/(Decrease) in Cash (A+B+C) | C24: =C11+C17+C22 -> 1.3096724e-10
B25: Add: Opening Cash & Bank Balance (FY2025) | C25: ='Historical Financials'!F40 -> 5529
B26: Closing Cash & Bank Balance (FY2026, computed) | C26: =C24+C25 -> 5529
B27: Closing Cash per Budgeted Balance Sheet (check) | C27: ='Budgeted Balance Sheet'!D15 -> 5529
B28: Difference (should be 0) | C28: =C26-C27 -> 1.3096724e-10

Sheet Sensitivity Analysis
A1: FY2026 Budget — Sensitivity Analysis
A2: Impact of three key downside risks on Budgeted EBITDA and PAT (Rs. Million).
A4: Base Case (from Budgeted P&L)
B5: Particulars | C5: Base Case
B6: Revenue from Operations | D6: ='Budgeted P&L'!D5 -> 1693893.8
B7: EBITDA | D7: ='Budgeted P&L'!D10 -> 220206.19
B8: EBITDA Margin % | D8: =D7/D6 -> 0.13
B9: PAT | D9: ='Budgeted P&L'!D20 -> 151943.64
A11: Risk Scenarios
B12: Risk Scenario | C12: Shock Applied | D12: Revised EBITDA | E12: EBITDA Impact | F12: Revised PAT | G12: PAT Impact | H12: Interpretation
B13: 1. Volume/Revenue growth 5pp lower than budgeted | C13: Revenue growth cut from ~10.8% to ~5.8% (i.e. Revenue x (1.058/1.108)) | D13: =(('Budgeted P&L'!D5*(1.058/1.108)))-(((('Budgeted P&L'!D5*(1.058/1.108)))*(Assumptions!$D$10))+((('Budgeted P&L'!D5*(1.058/1.108)))*(Assumptions!$D$11))+((('Budgeted P&L'!D5*(1.058/1.108)))*(Assumptions!$D$12))) -> 210269.09 | E13: =D13-D7 -> -9937.1024 | F13: =((((('Budgeted P&L'!D5*(1.058/1.108)))-(((('Budgeted P&L'!D5*(1.058/1.108)))*(Assumptions!$D$10))+((('Budgeted P&L'!D5*(1.058/1.108)))*(Assumptions!$D$11))+((('Budgeted P&L'!D5*(1.058/1.108)))*(Assumptions!$D$12))))-('Budgeted P&L'!D12))+('Budgeted P&L'!D14)-('Budgeted P&L'!D15)+('Budgeted P&L'!D16)+('Budgeted P&L'!D17))*(1-(Assumptions!$D$22)) -> 144581.24 | G13: =F13-D9 -> -7362.3991 | H13: A soft demand environment (industry PV growth stays near ICRA's low end, exports miss the 20% target) would hit EBITDA hard because ~87% of costs are variable/semi-variable with revenue, while Employee Cost and D&A stay largely fixed in the near term.
B14: 2. Raw material cost 10% higher than budgeted | C14: COGS % of Revenue up from 71.3% to 78.4% (71.3% x 1.10) | D14: =('Budgeted P&L'!D5)-((('Budgeted P&L'!D5)*(Assumptions!$D$10*1.1))+(('Budgeted P&L'!D5)*(Assumptions!$D$11))+(('Budgeted P&L'!D5)*(Assumptions!$D$12))) -> 99431.564 | E14: =D14-D7 -> -120774.62 | F14: =(((('Budgeted P&L'!D5)-((('Budgeted P&L'!D5)*(Assumptions!$D$10*1.1))+(('Budgeted P&L'!D5)*(Assumptions!$D$11))+(('Budgeted P&L'!D5)*(Assumptions!$D$12))))-('Budgeted P&L'!D12))+('Budgeted P&L'!D14)-('Budgeted P&L'!D15)+('Budgeted P&L'!D16)+('Budgeted P&L'!D17))*(1-(Assumptions!$D$22)) -> 62461.718 | G14: =F14-D9 -> -89481.92 | H14: Tests a scenario where the firm/rising steel & commodity cost outlook (WSA, industry reports) is worse than budgeted and price hikes cannot fully offset it — the single biggest EBITDA swing factor given COGS is ~82% of total operating costs.
B15: 3. Employee cost 8% higher than budgeted (wage settlement / faster Kharkhoda hiring) | C15: Employee Cost % of Revenue up from 4.7% to 5.1% (4.7% x 1.08) | D15: =('Budgeted P&L'!D5)-((('Budgeted P&L'!D5)*(Assumptions!$D$10))+(('Budgeted P&L'!D5)*(Assumptions!$D$11*1.08))+(('Budgeted P&L'!D5)*(Assumptions!$D$12))) -> 213837.15 | E15: =D15-D7 -> -6369.0405 | F15: =(((('Budgeted P&L'!D5)-((('Budgeted P&L'!D5)*(Assumptions!$D$10))+(('Budgeted P&L'!D5)*(Assumptions!$D$11*1.08))+(('Budgeted P&L'!D5)*(Assumptions!$D$12))))-('Budgeted P&L'!D12))+('Budgeted P&L'!D14)-('Budgeted P&L'!D15)+('Budgeted P&L'!D16)+('Budgeted P&L'!D17))*(1-(Assumptions!$D$22)) -> 147224.82 | G15: =F15-D9 -> -4718.8221 | H15: Tests the risk of a larger-than-planned wage settlement or faster-than-planned hiring ramp for the new Kharkhoda plant — a smaller swing than volume or raw-material risk, since Employee Cost is only ~4.7% of revenue, but included because it is the least flexible of the three cost lines.
A17: Combined Downside Scenario (all three risks together)
B18: All three risks simultaneously | D18: =(('Budgeted P&L'!D5*(1.058/1.108)))-(((('Budgeted P&L'!D5*(1.058/1.108)))*(Assumptions!$D$10*1.1))+((('Budgeted P&L'!D5*(1.058/1.108)))*(Assumptions!$D$11*1.08))+((('Budgeted P&L'!D5*(1.058/1.108)))*(Assumptions!$D$12))) -> 88862.951 | E18: =D18-D7 -> -131343.24 | F18: =((((('Budgeted P&L'!D5*(1.058/1.108)))-(((('Budgeted P&L'!D5*(1.058/1.108)))*(Assumptions!$D$10*1.1))+((('Budgeted P&L'!D5*(1.058/1.108)))*(Assumptions!$D$11*1.08))+((('Budgeted P&L'!D5*(1.058/1.108)))*(Assumptions!$D$12))))-('Budgeted P&L'!D12))+('Budgeted P&L'!D14)-('Budgeted P&L'!D15)+('Budgeted P&L'!D16)+('Budgeted P&L'!D17))*(1-(Assumptions!$D$22)) -> 54631.433 | G18: =F18-D9 -> -97312.205 | H18: A simultaneous 'perfect storm' — useful as a stress-test floor for the budget, though the three risks are only partially correlated in practice.
B20: Reading the table: each scenario changes ONE driver on the Assumptions tab (holding all others at the base case) and reflows through the same P&L logic as the Budgeted P&L tab. Revenue-side risk (Scenario 1) has the largest EBITDA impact because nearly all of the cost base scales with revenue; the two cost-side risks (Scenarios 2 and 3) show how much of MSIL's margin is exposed to input-cost and wage inflation specifically. This is the mechanism required by the SOW: '2-3 key risks to the budget... impact on EBITDA and PAT.'
A25: Bull Case (mirror-image upside — all three drivers move favourably)
B26: Volume/Revenue growth 5pp higher + Raw material cost 10% lower + Employee cost 8% lower | D26: =(('Budgeted P&L'!D5*(1.158/1.108)))-(((('Budgeted P&L'!D5*(1.158/1.108)))*(Assumptions!$D$10*0.9))+((('Budgeted P&L'!D5*(1.158/1.108)))*(Assumptions!$D$11*0.92))+((('Budgeted P&L'!D5*(1.158/1.108)))*(Assumptions!$D$12))) -> 363024.49 | E26: =D26-D7 -> 142818.3 | F26: =((((('Budgeted P&L'!D5*(1.158/1.108)))-(((('Budgeted P&L'!D5*(1.158/1.108)))*(Assumptions!$D$10*0.9))+((('Budgeted P&L'!D5*(1.158/1.108)))*(Assumptions!$D$11*0.92))+((('Budgeted P&L'!D5*(1.158/1.108)))*(Assumptions!$D$12))))-('Budgeted P&L'!D12))+('Budgeted P&L'!D14)-('Budgeted P&L'!D15)+('Budgeted P&L'!D16)+('Budgeted P&L'!D17))*(1-(Assumptions!$D$22)) -> 257757.71 | G26: =F26-D9 -> 105814.08 | H26: Mirror-image favourable scenario (stronger demand, softer commodity costs, tighter cost control) — an equally-illustrative upside stress-test ceiling for the budget.
A28: Scenario Summary — Bear / Base / Bull
B29: Scenario | C29: EBITDA (Rs mn) | D29: EBITDA Margin % | E29: PAT (Rs mn) | F29: PAT Margin % | G29: vs. Base PAT
B30: Bear (combined downside) | C30: =D18 -> 88862.951 | D30: =D18/D6 -> 0.052460758 | E30: =F18 -> 54631.433 | F30: =F18/D6 -> 0.032251983 | G30: =F18-D9 -> -97312.205
B31: Base (FY2026 Budget) | C31: =D7 -> 220206.19 | D31: =D7/D6 -> 0.13 | E31: =D9 -> 151943.64 | F31: =D9/D6 -> 0.089700807 | G31: 0
B32: Bull (mirror-image upside) | C32: =D26 -> 363024.49 | D32: =D26/D6 -> 0.21431361 | E32: =F26 -> 257757.71 | F32: =F26/D6 -> 0.15216876 | G32: =F26-D9 -> 105814.08
A34: Break-Even Analysis
B35: Relative COGS increase that fully erodes FY2026's budgeted PAT growth vs FY2025 | H35: Solved using Excel Goal Seek / manual iteration on cell X15 (relative COGS shock %) so that PAT equals FY2025 actual PAT.
B36: Relative COGS shock % (solve for PAT = FY25 PAT) | C36: Implied PAT at this COGS shock -> | D36: =(((('Budgeted P&L'!D5)-(('Budgeted P&L'!D5)*(Assumptions!$D$10*(1+M36)))-(('Budgeted P&L'!D5)*(Assumptions!$D$11))-(('Budgeted P&L'!D5)*(Assumptions!$D$12)))-('Budgeted P&L'!D12))+('Budgeted P&L'!D14)-('Budgeted P&L'!D15)+('Budgeted P&L'!D16)+('Budgeted P&L'!D17))*(1-(Assumptions!$D$22)) -> 144964.05 | E36: ='Historical Financials'!F21 -> 145002 | F36: <- FY2025 Actual PAT (target) | M36: 0.0078
B38: Solved (by iteration) that a Cost-of-Materials overrun of just +0.8% relative to the 71.3% budgeted ratio (i.e. COGS rising to only ~71.85% of revenue — barely half a percentage point) is sufficient, on its own, to erode all of FY2026's budgeted PAT growth and push PAT back down to FY2025's actual level (Rs 145,002 mn). This is a materially smaller shock than the +10% tested in Scenario 2, and it is the single most important number in this report: the entire year's profit growth rests on a margin of safety of well under one percentage point on the Company's largest cost line.

Sheet Charts
A1: Charts — FY2022-FY2026E Trends & Sensitivity
A2: Underlying data table below feeds the charts; all cells are formulas linked to other tabs.
B4: Particulars | C4: FY2022 | D4: FY2023 | E4: FY2024 | F4: FY2025 | G4: FY2026E
B5: Revenue from Operations | C5: ='Historical Financials'!C6 -> 883298 | D5: ='Historical Financials'!D6 -> 1184099 | E5: ='Historical Financials'!E6 -> 1418582 | F5: ='Historical Financials'!F6 -> 1529130 | G5: ='Budgeted P&L'!D5 -> 1693893.8
B6: EBITDA | C6: ='Historical Financials'!C11 -> 57062 | D6: ='Historical Financials'!D11 -> 130944 | E6: ='Historical Financials'!E11 -> 185263 | F6: ='Historical Financials'!F11 -> 201563 | G6: ='Budgeted P&L'!D10 -> 220206.19
B7: PAT | C7: ='Historical Financials'!C21 -> 38795 | D7: ='Historical Financials'!D21 -> 82637 | E7: ='Historical Financials'!E21 -> 134882 | F7: ='Historical Financials'!F21 -> 145002 | G7: ='Budgeted P&L'!D20 -> 151943.64
B8: EBITDA Margin % | C8: =C6/C5 -> 0.064601075 | D8: =D6/D5 -> 0.11058535 | E8: =E6/E5 -> 0.13059731 | F8: =F6/F5 -> 0.13181548 | G8: =G6/G5 -> 0.13
B9: PAT Margin % | C9: =C7/C5 -> 0.043920625 | D9: =D7/D5 -> 0.069788928 | E9: =E7/E5 -> 0.095082272 | F9: =F7/F5 -> 0.09482647 | G9: =G7/G5 -> 0.089700807
B10: COGS % of Revenue | C10: ='Historical Financials'!C7/'Historical Financials'!C6 -> 0.748539 | D10: ='Historical Financials'!D7/'Historical Financials'!D6 -> 0.72407797 | E10: ='Historical Financials'!E7/'Historical Financials'!E6 -> 0.70469243 | F10: ='Historical Financials'!F7/'Historical Financials'!F6 -> 0.7059766 | G10: =Assumptions!D10 -> 0.713
B11: Employee Cost % of Revenue | C11: ='Historical Financials'!C8/'Historical Financials'!C6 -> 0.045816927 | D11: ='Historical Financials'!D8/'Historical Financials'!D6 -> 0.044327375 | E11: ='Historical Financials'!E8/'Historical Financials'!E6 -> 0.044161705 | F11: ='Historical Financials'!F8/'Historical Financials'!F6 -> 0.045068765 | G11: =Assumptions!D11 -> 0.047
B12: Other Opex % of Revenue | C12: ='Historical Financials'!C9/'Historical Financials'!C6 -> 0.141043 | D12: ='Historical Financials'!D9/'Historical Financials'!D6 -> 0.12100931 | E12: ='Historical Financials'!E9/'Historical Financials'!E6 -> 0.12054855 | F12: ='Historical Financials'!F9/'Historical Financials'!F6 -> 0.11713916 | G12: =Assumptions!D12 -> 0.11

Sheet Ratio Analysis
A1: Ratio Analysis — FY2022 to FY2026E
A2: Profitability, efficiency and leverage ratios computed from the Historical Financials and Budgeted P&L/Balance Sheet tabs.
B4: Ratio | C4: FY2022 | D4: FY2023 | E4: FY2024 | F4: FY2025 | G4: FY2026E | H4: Formula / Note
A5: Profitability Ratios
B6: EBITDA Margin % | C6: ='Historical Financials'!C12 -> 0.064601075 | D6: ='Historical Financials'!D12 -> 0.11058535 | E6: ='Historical Financials'!E12 -> 0.13059731 | F6: ='Historical Financials'!F12 -> 0.13181548 | G6: ='Budgeted P&L'!D11 -> 0.13 | H6: EBITDA / Revenue
B7: EBIT Margin % | C7: ='Historical Financials'!C14/'Historical Financials'!C6 -> 0.033026227 | D7: ='Historical Financials'!D14/'Historical Financials'!D6 -> 0.069659716 | E7: ='Historical Financials'!E14/'Historical Financials'!E6 -> 0.093547641 | F7: ='Historical Financials'!F14/'Historical Financials'!F6 -> 0.09513972 | G7: ='Budgeted P&L'!D13/'Budgeted P&L'!D5 -> 0.091356065 | H7: EBIT / Revenue
B8: PAT Margin % | C8: ='Historical Financials'!C22 -> 0.043920625 | D8: ='Historical Financials'!D22 -> 0.069788928 | E8: ='Historical Financials'!E22 -> 0.095082272 | F8: ='Historical Financials'!F22 -> 0.09482647 | G8: ='Budgeted P&L'!D21 -> 0.089700807 | H8: PAT / Revenue
B9: Return on Equity (ROE) | C9: ='Historical Financials'!C21/'Historical Financials'!C31 -> 0.070111235 | D9: ='Historical Financials'!D21/'Historical Financials'!D31 -> 0.11077316 | E9: ='Historical Financials'!E21/'Historical Financials'!E31 -> 0.15750619 | F9: ='Historical Financials'!F21/'Historical Financials'!F31 -> 0.15066724 | G9: ='Budgeted P&L'!D20/'Budgeted Balance Sheet'!D6 -> 0.1401318 | H9: PAT / Closing Shareholders' Equity
B10: Return on Capital Employed (ROCE) | C10: ='Historical Financials'!C14/('Historical Financials'!C31+'Historical Financials'!C32) -> 0.052318011 | D10: ='Historical Financials'!D14/('Historical Financials'!D31+'Historical Financials'!D32) -> 0.10874936 | E10: ='Historical Financials'!E14/('Historical Financials'!E31+'Historical Financials'!E32) -> 0.15474972 | F10: ='Historical Financials'!F14/('Historical Financials'!F31+'Historical Financials'!F32) -> 0.15102843 | G10: ='Budgeted P&L'!D13/('Budgeted Balance Sheet'!D6+'Budgeted Balance Sheet'!D7) -> 0.14260325 | H10: EBIT / (Equity + Borrowings) — pre-tax capital productivity
B11: Return on Assets (ROA) | C11: ='Historical Financials'!C21/'Historical Financials'!C42 -> 0.066859573 | D11: ='Historical Financials'!D21/'Historical Financials'!D42 -> 0.10481435 | E11: ='Historical Financials'!E21/'Historical Financials'!E42 -> 0.15079055 | F11: ='Historical Financials'!F21/'Historical Financials'!F42 -> 0.14295813 | G11: ='Budgeted P&L'!D20/'Budgeted Balance Sheet'!D18 -> 0.13313304 | H11: PAT / Total Assets
A12: Efficiency Ratios
B13: Asset Turnover (x) | C13: ='Historical Financials'!C6/'Historical Financials'!C42 -> 1.5222819 | D13: ='Historical Financials'!D6/'Historical Financials'!D42 -> 1.5018766 | E13: ='Historical Financials'!E6/'Historical Financials'!E42 -> 1.5858956 | F13: ='Historical Financials'!F6/'Historical Financials'!F42 -> 1.5075762 | G13: ='Budgeted P&L'!D5/'Budgeted Balance Sheet'!D18 -> 1.48419 | H13: Revenue / Total Assets
B14: Fixed Asset Turnover (x) | C14: ='Historical Financials'!C6/'Historical Financials'!C36 -> 5.505644 | D14: ='Historical Financials'!D6/'Historical Financials'!D36 -> 3.765308 | E14: ='Historical Financials'!E6/'Historical Financials'!E36 -> 4.0629121 | F14: ='Historical Financials'!F6/'Historical Financials'!F36 -> 3.8209336 | G14: ='Budgeted P&L'!D5/'Budgeted Balance Sheet'!D12 -> 4.3478261 | H14: Revenue / Fixed Assets — capacity utilisation proxy
B15: Net Current Assets, % of Revenue | C15: ='Historical Financials'!C41/'Historical Financials'!C6 -> -0.079019765 | D15: ='Historical Financials'!D41/'Historical Financials'!D6 -> -0.072826681 | E15: ='Historical Financials'!E41/'Historical Financials'!E6 -> -0.070540159 | F15: ='Historical Financials'!F41/'Historical Financials'!F6 -> -0.06479763 | G15: ='Budgeted Balance Sheet'!D16/'Budgeted P&L'!D5 -> -0.075 | H15: Working-capital intensity (negative = funding source)
A16: Leverage & Coverage Ratios
B17: Debt / Equity (x) | C17: ='Historical Financials'!C32/'Historical Financials'!C31 -> 0.0076897359 | D17: ='Historical Financials'!D32/'Historical Financials'!D31 -> 0.016723816 | E17: ='Historical Financials'!E32/'Historical Financials'!E31 -> 0.0013849316 | F17: ='Historical Financials'!F32/'Historical Financials'!F31 -> 0.00090399096 | G17: ='Budgeted Balance Sheet'!D7/'Budgeted Balance Sheet'!D6 -> 0.0008023677 | H17: Borrowings / Shareholders' Equity — MSIL is near debt-free throughout
B18: Interest Coverage (EBIT/Finance Cost, x) | C18: ='Historical Financials'!C14/'Historical Financials'!C16 -> 23.042654 | D18: ='Historical Financials'!D14/'Historical Financials'!D16 -> 32.692826 | E18: ='Historical Financials'!E14/'Historical Financials'!E16 -> 68.545971 | F18: ='Historical Financials'!F14/'Historical Financials'!F16 -> 74.912976 | G18: ='Budgeted P&L'!D13/'Budgeted P&L'!D15 -> 79.684587 | H18: EBIT / Finance Cost — very high throughout given minimal debt
B19: Effective Tax Rate | C19: ='Historical Financials'!C20/'Historical Financials'!C19 -> 0.17408243 | D19: ='Historical Financials'!D20/'Historical Financials'!D19 -> 0.20832136 | E19: ='Historical Financials'!E20/'Historical Financials'!E19 -> 0.22590605 | F19: ='Historical Financials'!F20/'Historical Financials'!F19 -> 0.26094801 | G19: ='Budgeted P&L'!D19/'Budgeted P&L'!D18 -> 0.2591 | H19: Tax Expense / PBT
A20: Growth & Cash Generation
B21: Revenue Growth % YoY | D21: ='Historical Financials'!D6/'Historical Financials'!C6-1 -> 0.34054306 | E21: ='Historical Financials'!E6/'Historical Financials'!D6-1 -> 0.19802652 | F21: ='Historical Financials'!F6/'Historical Financials'!E6-1 -> 0.077928523 | G21: ='Budgeted P&L'!D5/'Budgeted P&L'!C5-1 -> 0.10775
B22: EBITDA Growth % YoY | D22: ='Historical Financials'!D11/'Historical Financials'!C11-1 -> 1.2947671 | E22: ='Historical Financials'!E11/'Historical Financials'!D11-1 -> 0.41482619 | F22: ='Historical Financials'!F11/'Historical Financials'!E11-1 -> 0.08798303 | G22: ='Budgeted P&L'!D10/'Budgeted P&L'!C10-1 -> 0.092493109
B23: PAT Growth % YoY | D23: ='Historical Financials'!D21/'Historical Financials'!C21-1 -> 1.1300941 | E23: ='Historical Financials'!E21/'Historical Financials'!D21-1 -> 0.63222285 | F23: ='Historical Financials'!F21/'Historical Financials'!E21-1 -> 0.075028543 | G23: ='Budgeted P&L'!D20/'Budgeted P&L'!C20-1 -> 0.047872702
B24: Implied Capex (Rs mn) | D24: =('Historical Financials'!D36+'Historical Financials'!D37)-('Historical Financials'!C36+'Historical Financials'!C37)+'Historical Financials'!D13 -> 202467 | E24: =('Historical Financials'!E36+'Historical Financials'!E37)-('Historical Financials'!D36+'Historical Financials'!D37)+'Historical Financials'!E13 -> 87710 | F24: =('Historical Financials'!F36+'Historical Financials'!F37)-('Historical Financials'!E36+'Historical Financials'!E37)+'Historical Financials'!F13 -> 109203 | G24: =('Budgeted Balance Sheet'!D12+'Budgeted Balance Sheet'!D13)-('Historical Financials'!F36+'Historical Financials'!F37)+'Budgeted P&L'!D12 -> 55703.589 | H24: Closing (Fixed+Intangible) − Opening (Fixed+Intangible) + D&A; back-solved, not separately disclosed
B25: Simplified FCF = PAT + D&A − Capex (Rs mn) | D25: ='Historical Financials'!D21+'Historical Financials'!D13-D24 -> -71370 | E25: ='Historical Financials'!E21+'Historical Financials'!E13-E24 -> 99730 | F25: ='Historical Financials'!F21+'Historical Financials'!F13-F24 -> 91881 | G25: ='Budgeted P&L'!D20+'Budgeted P&L'!D12-G24 -> 161698.77 | H25: Illustrative pre-working-capital FCF proxy (full historical CF statements were not part of the source data)

Sheet Quarterly Phasing
A1: FY2026 Budget — Illustrative Quarterly Phasing
A2: Phases the annual budget into Q1-Q4 using typical Indian passenger-vehicle industry seasonality (illustrative weights, not derived from MSIL's own undisclosed quarterly split).
B4: Particulars | C4: Q1 (Apr-Jun) | D4: Q2 (Jul-Sep) | E4: Q3 (Oct-Dec) | F4: Q4 (Jan-Mar) | G4: FY2026 Total | H4: Note
A5: Phasing Weights (illustrative — see note)
B6: Seasonality Weight % | C6: 0.23 | D6: 0.24 | E6: 0.26 | F6: 0.27 | G6: =SUM(C6:F6) -> 1 | H6: Q1 softest (summer/monsoon onset); Q3 strongest (Navratri/Dussehra/Diwali festive demand); Q4 firm (fiscal year-end dealer stocking, new launches).
A8: Phased P&L (Rs mn)
B9: Revenue from Operations | C9: ='Budgeted P&L'!$D$5*C6 -> 389595.56 | D9: ='Budgeted P&L'!$D$5*D6 -> 406534.5 | E9: ='Budgeted P&L'!$D$5*E6 -> 440412.38 | F9: ='Budgeted P&L'!$D$5*F6 -> 457351.31 | G9: =SUM(C9:F9) -> 1693893.8
B10: EBITDA (flat margin assumption) | C10: ='Budgeted P&L'!$D$10*C6 -> 50647.423 | D10: ='Budgeted P&L'!$D$10*D6 -> 52849.485 | E10: ='Budgeted P&L'!$D$10*E6 -> 57253.609 | F10: ='Budgeted P&L'!$D$10*F6 -> 59455.671 | G10: =SUM(C10:F10) -> 220206.19
B11: PAT (flat margin assumption) | C11: ='Budgeted P&L'!$D$20*C6 -> 34947.037 | D11: ='Budgeted P&L'!$D$20*D6 -> 36466.473 | E11: ='Budgeted P&L'!$D$20*E6 -> 39505.346 | F11: ='Budgeted P&L'!$D$20*F6 -> 41024.782 | G11: =SUM(C11:F11) -> 151943.64
B13: EBITDA Margin % (check — should be flat across quarters) | C13: =C10/C9 -> 0.13 | D13: =D10/D9 -> 0.13 | E13: =E10/E9 -> 0.13 | F13: =F10/F9 -> 0.13
B15: These quarterly weights are an illustrative phasing based on well-documented Indian passenger-vehicle industry seasonality (weak Q1, festive-led Q3 strength, fiscal year-end Q4 push) — MSIL does not publicly disclose a quarterly budget, so this is presented as a planning/monitoring aid for the FP&A team (e.g. to flag early in the year if Q1 actuals are tracking materially off the ~23% pace), not as a precise reconstruction of the Company's own internal phasing.
